Traceback (most recent call last):
  File "/home/randall/anaconda3/envs/compecon/lib/python3.8/site-packages/jupyter_cache/executors/utils.py", line 51, in single_nb_execution
    executenb(
  File "/home/randall/anaconda3/envs/compecon/lib/python3.8/site-packages/nbclient/client.py", line 1117, in execute
    return NotebookClient(nb=nb, resources=resources, km=km, **kwargs).execute()
  File "/home/randall/anaconda3/envs/compecon/lib/python3.8/site-packages/nbclient/util.py", line 78, in wrapped
    return just_run(coro(*args, **kwargs))
  File "/home/randall/anaconda3/envs/compecon/lib/python3.8/site-packages/nbclient/util.py", line 57, in just_run
    return loop.run_until_complete(coro)
  File "/home/randall/anaconda3/envs/compecon/lib/python3.8/asyncio/base_events.py", line 616, in run_until_complete
    return future.result()
  File "/home/randall/anaconda3/envs/compecon/lib/python3.8/site-packages/nbclient/client.py", line 558, in async_execute
    await self.async_execute_cell(
  File "/home/randall/anaconda3/envs/compecon/lib/python3.8/site-packages/nbclient/client.py", line 862, in async_execute_cell
    self._check_raise_for_error(cell, exec_reply)
  File "/home/randall/anaconda3/envs/compecon/lib/python3.8/site-packages/nbclient/client.py", line 765, in _check_raise_for_error
    raise CellExecutionError.from_cell_and_msg(cell, exec_reply_content)
nbclient.exceptions.CellExecutionError: An error occurred while executing the following cell:
------------------
from compecon import MCP, jacobian
import numpy as np

x0 = [0.5, 0.5]    
------------------

[0;31m---------------------------------------------------------------------------[0m
[0;31mModuleNotFoundError[0m                       Traceback (most recent call last)
[0;32m/tmp/ipykernel_48116/31393211.py[0m in [0;36m<module>[0;34m[0m
[0;32m----> 1[0;31m [0;32mfrom[0m [0mcompecon[0m [0;32mimport[0m [0mMCP[0m[0;34m,[0m [0mjacobian[0m[0;34m[0m[0;34m[0m[0m
[0m[1;32m      2[0m [0;32mimport[0m [0mnumpy[0m [0;32mas[0m [0mnp[0m[0;34m[0m[0;34m[0m[0m
[1;32m      3[0m [0;34m[0m[0m
[1;32m      4[0m [0mx0[0m [0;34m=[0m [0;34m[[0m[0;36m0.5[0m[0;34m,[0m [0;36m0.5[0m[0;34m][0m[0;34m[0m[0;34m[0m[0m

[0;32m~/anaconda3/envs/compecon/lib/python3.8/site-packages/compecon/__init__.py[0m in [0;36m<module>[0;34m[0m
[1;32m     16[0m [0;32mfrom[0m [0;34m.[0m[0mocmodel[0m [0;32mimport[0m [0mOCmodel[0m[0;34m,[0m [0mOCoptions[0m[0;34m[0m[0;34m[0m[0m
[1;32m     17[0m [0;32mfrom[0m [0;34m.[0m[0mtools[0m [0;32mimport[0m [0;34m*[0m[0;34m[0m[0;34m[0m[0m
[0;32m---> 18[0;31m [0;32mfrom[0m [0;34m.[0m[0mquad[0m [0;32mimport[0m [0;34m*[0m[0;34m[0m[0;34m[0m[0m
[0m[1;32m     19[0m [0;32mfrom[0m [0;34m.[0m[0mddpmodel[0m [0;32mimport[0m [0mDDPmodel[0m[0;34m[0m[0;34m[0m[0m
[1;32m     20[0m [0;32mfrom[0m [0;34m.[0m[0mlqmodel[0m [0;32mimport[0m [0mLQmodel[0m[0;34m[0m[0;34m[0m[0m

[0;32m~/anaconda3/envs/compecon/lib/python3.8/site-packages/compecon/quad.py[0m in [0;36m<module>[0;34m[0m
[1;32m     21[0m [0;32mimport[0m [0mscipy[0m[0;34m.[0m[0mlinalg[0m [0;32mas[0m [0mla[0m[0;34m[0m[0;34m[0m[0m
[1;32m     22[0m [0;32mfrom[0m [0mscipy[0m[0;34m.[0m[0mspecial[0m [0;32mimport[0m [0mgammaln[0m[0;34m[0m[0;34m[0m[0m
[0;32m---> 23[0;31m [0;32mimport[0m [0msympy[0m [0;32mas[0m [0msym[0m[0;34m[0m[0;34m[0m[0m
[0m[1;32m     24[0m [0;31m# from .ce_util import ckron, gridmake[0m[0;34m[0m[0;34m[0m[0;34m[0m[0m
[1;32m     25[0m [0;32mfrom[0m [0;34m.[0m[0mtools[0m [0;32mimport[0m [0mckron[0m[0;34m,[0m [0mgridmake[0m   [0;31m#todo NOTICE THAT I AM DEPARTING FROM ORIGINAL HERE!!!  #FIXME GET THIS MODULE CONSISTENT[0m[0;34m[0m[0;34m[0m[0m

[0;31mModuleNotFoundError[0m: No module named 'sympy'
ModuleNotFoundError: No module named 'sympy'

